<?xml version="1.0"?>
<robot xmlns:xacro="http://www.ros.org/wiki/xacro" >
    
    <xacro:include filename="materials.xacro" />
    <xacro:include filename="inertial_macros.xacro" />


    <!-- BASE LINK-->

    <link name="base_link">

    </link>

    <joint name="base_footprint_joint" type="fixed" >
        <parent link="base_link" />
        <child link="base_footprint" />
        <origin xyz="0 0 0" rpy="0 0 0" />
    </joint>

    <link name="base_footprint">

    </link>

    <!-- CHASSIS LINK -->

    <joint name="chassis_joint" type="fixed">
        <parent link="base_link" />
        <child link="chassis" />
        <origin xyz="-0.33 0 0" />
    </joint>

    <link name="chassis">
        <visual>
            <!-- box origin -->
            <origin xyz="0.33 0 0.1405" />
            <!-- stl origin -->
            <!--origin xyz="0.125 0 0" /-->
            <geometry>
                <box size="0.66 0.61 0.281" />
                <!-- importing a mesh of the bunker mini robot -->
                <!--mesh filename="package://bunker_mini/description/bunker_mini.stl"/-->
            </geometry>
            <material name="white" />
        </visual>
        <collision>
            <origin xyz="0.33 0 0.1405" />
            <geometry>
                <box size="0.66 0.61 0.281" />
            </geometry>
        </collision>
        <xacro:inertial_box mass="2" x="0.66" y="0.61" z="0.281">
            <origin xyz="0.33 0 0.1405" rpy="0 0 0" />
        </xacro:inertial_box>
    </link>

    <gazebo reference="chassis">
        <material>Gazebo/White</material>
    </gazebo>

    <joint name="front_diamond_joint" type="fixed">
        <parent link="base_link" />
        <child link="front_diamond" />
        <origin xyz="-0.33 0 0" />

    </joint>

    <link name="front_diamond">
        <visual>
            <!-- front diamond origin -->
            <origin xyz="0.6 0 0.28" rpy="0 0 ${pi/4}" />
            <geometry>
                <box size="0.03 0.03 0.02" />
            </geometry>
            <material name="blue" />
        </visual>
        <collision>
            <origin xyz="0.6 0 0.28" rpy="0 0 ${pi/4}" />
            <geometry>
                <box size="0.03 0.03 0.02" />
            </geometry>
        </collision>
        <xacro:inertial_box mass="0.1" x="0.03" y="0.03" z="0.02">
            <origin xyz="0.52 0 0.28" rpy="0 0 ${pi/4}" />
        </xacro:inertial_box>
    </link>

    <gazebo reference="front_diamond">
        <material>Gazebo/Blue</material>
    </gazebo>

    <!-- LEFT WHEEL LINK -->

    <joint name="left_wheel_joint" type="continuous">
        <parent link="base_link" />
        <child link="left_wheel" />
        <!-- CHANGE WHEEL OFFSET TO MATCH REAL ROBOT -->
        <origin xyz="0 0.25 0" rpy="${-pi/2} 0 0" />
        <axis xyz=" 0 0 1" />
    </joint>

    <link name="left_wheel">
        <visual>
            <geometry>
                <!-- CHANGE WHEEL RADIUS TO MATCH UP WITH REAL ROBOT FOR ODOM DATA -->
                <cylinder radius="0.05" length="0.04" />
            </geometry>
            <material name="blue" />
        </visual>
        <collision>
            <geometry>
                <!-- CHANGE WHEEL RADIUS TO MATCH UP WITH REAL ROBOT FOR ODOM DATA -->
                <cylinder radius="0.05" length="0.04" />
            </geometry>
        </collision>
        <xacro:inertial_cylinder mass="0.1" length="0.04" radius="0.05">
            <origin xyz="0 0 0 " rpy="0 0 0" />
        </xacro:inertial_cylinder>
    </link>

    <gazebo reference="left_wheel">
        <material>Gazebo/Blue</material>
    </gazebo>

    <!-- RIGHT WHEEL LINK -->

    <joint name="right_wheel_joint" type="continuous">
        <parent link="base_link" />
        <child link="right_wheel" />
        <!-- CHANGE WHEEL OFFSET TO MATCH REAL ROBOT -->
        <origin xyz="0 -0.25 0" rpy="${pi/2} 0 0" />
        <axis xyz=" 0 0 -1" />
    </joint>

    <link name="right_wheel">
        <visual>
            <geometry>
                <!-- CHANGE WHEEL RADIUS TO MATCH UP WITH REAL ROBOT FOR ODOM DATA -->
                <cylinder radius="0.05" length="0.04" />
            </geometry>
            <material name="blue" />
        </visual>
        <collision>
            <geometry>
                <!-- CHANGE WHEEL RADIUS TO MATCH UP WITH REAL ROBOT FOR ODOM DATA -->
                <cylinder radius="0.05" length="0.04" />
            </geometry>
        </collision>
        <xacro:inertial_cylinder mass="0.1" length="0.04" radius="0.05">
            <origin xyz="0 0 0 " rpy="0 0 0" />
        </xacro:inertial_cylinder>
    </link>

    <gazebo reference="right_wheel">
        <material>Gazebo/Blue</material>
    </gazebo>


    <!-- FRONT CASTER WHEEL LINK -->

    <joint name="front_caster_wheel_joint" type="fixed">
        <parent link="base_link" />
        <child link="front_caster_wheel" />
        <origin xyz="0.25 0 0" />
    </joint>

    <link name="front_caster_wheel">
        <visual>
            <geometry>
                <sphere radius="0.05" />
            </geometry>
            <material name="black" />
        </visual>
        <collision>
            <geometry>
                <sphere radius="0.05" />
            </geometry>
        </collision>
        <xacro:inertial_sphere mass="0.1" radius="0.05">
            <origin xyz="0 0 0" rpy="0 0 0" />
        </xacro:inertial_sphere>
    </link>

    <gazebo reference="front_caster_wheel">
        <material>Gazebo/Black</material>
        <mu1 value="0.001" />
        <mu2 value="0.001" />
    </gazebo>

    <!-- REAR CASTER WHEEL LINK -->

    <joint name="rear_caster_wheel_joint" type="fixed">
        <parent link="base_link" />
        <child link="rear_caster_wheel" />
        <origin xyz="-0.25 0 0" />
    </joint>

    <link name="rear_caster_wheel">
        <visual>
            <geometry>
                <sphere radius="0.05" />
            </geometry>
            <material name="black" />
        </visual>
        <collision>
            <geometry>
                <sphere radius="0.05" />
            </geometry>
        </collision>
        <xacro:inertial_sphere mass="0.1" radius="0.05">
            <origin xyz="0 0 0" rpy="0 0 0" />
        </xacro:inertial_sphere>
    </link>

    <gazebo reference="rear_caster_wheel">
        <material>Gazebo/Black</material>
        <mu1 value="0.001" />
        <mu2 value="0.001" />
    </gazebo>

</robot>